<?xml version="1.0"?>
<robot name="robot" xmlns:xacro="http://www.ros.org/wiki/xacro">
   
   <material name="grey">
      <color rgba="0.7 0.7 0.7 1"/>
   </material>

   <material name="green">
      <color rgba="0 0.6 0 1"/>  
   </material>

   <material name="white">
      <color rgba="1 1 1 1"/>
   </material>

   <material name="black">
      <color rgba="0.0 0.0 0.0 1.0"/>
    </material>
  
    <material name="blue">
      <color rgba="0.0 0.0 0.8 1.0"/>
    </material>
  
    <material name="orange">
      <color rgba="${255/255} ${108/255} ${10/255} 1.0"/>
    </material>
  
    <material name="brown">
      <color rgba="${222/255} ${207/255} ${195/255} 1.0"/>
    </material>
  
    <material name="red">
      <color rgba="0.8 0.0 0.0 1.0"/>
    </material>

   <!-- Chassis -->
   <link name="base_footprint"></link>
   <link name="base_link">
      <inertial>
         <mass value="2.0"/>
         <origin xyz="0 0 0" rpy="0 0 0"/>
         <inertia ixx="0.1" ixy="0.0" ixz="0.0" iyy="0.1" iyz="0.0" izz="0.1"/>
      </inertial>
      <visual>
         <geometry>
            <box size="0.6 0.4 0.1" />
         </geometry>
         <origin xyz="0 0 0" rpy="0 0 0"/>
         <material name="green"/>
      </visual>
      <collision>
         <geometry>
            <box size="0.6 0.4 0.1" />
         </geometry>
         <origin xyz="0 0 0" rpy="0 0 0"/>
      </collision>
   </link>
   
   
   <link name="gps">
      <inertial>
         <mass value="5.0"/>
         <origin xyz="0 0 0" rpy="0 0 0"/>
         <inertia ixx="0.1" ixy="0.0" ixz="0.0" iyy="0.1" iyz="0.0" izz="0.1"/>
      </inertial>
      <visual>
         <geometry>
            <box size="0.02 0.02 0.02" />
         </geometry>
         <origin xyz="0 0 0" rpy="0 0 0"/>
         <material name="black"/>
      </visual>
      <collision>
         <geometry>
            <box size="0.02 0.02 0.02" />
         </geometry>
         <origin xyz="0 0 0" rpy="0 0 0"/>
      </collision>
   </link>

   <link name="camera">
      <inertial>
         <mass value="5.0"/>
         <origin xyz="0 0 0" rpy="0 0 0"/>
         <inertia ixx="0.1" ixy="0.0" ixz="0.0" iyy="0.1" iyz="0.0" izz="0.1"/>
      </inertial>
      <visual>
         <geometry>
            <box size="0.05 0.05 0.05" />
         </geometry>
         <origin xyz="0 0 0" rpy="0 0 0"/>
         <material name="orange"/>
      </visual>
      <collision>
         <geometry>
            <box size="0.05 0.05 0.05" />
         </geometry>
         <origin xyz="0 0 0" rpy="0 0 0"/>
      </collision>
   </link>
   
   <link name="ultrasonic">
      <inertial>
         <mass value="5.0"/>
         <origin xyz="0 0 0" rpy="0 0 0"/>
         <inertia ixx="0.1" ixy="0.0" ixz="0.0" iyy="0.1" iyz="0.0" izz="0.1"/>
      </inertial>
      <visual>
         <geometry>
            <box size="0.02 0.02 0.02" />
         </geometry>
         <origin xyz="0 0 0" rpy="0 0 0"/>
         <material name="blue"/>
      </visual>
      <collision>
         <geometry>
            <box size="0.02 0.02 0.02" />
         </geometry>
         <origin xyz="0 0 0" rpy="0 0 0"/>
      </collision>
   </link>
   
   <link name="ultrasonic2">
      <inertial>
         <mass value="5.0"/>
         <origin xyz="0 0 0" rpy="0 0 0"/>
         <inertia ixx="0.1" ixy="0.0" ixz="0.0" iyy="0.1" iyz="0.0" izz="0.1"/>
      </inertial>
      <visual>
         <geometry>
            <box size="0.02 0.02 0.02" />
         </geometry>
         <origin xyz="0 0 0" rpy="0 0 0"/>
         <material name="blue"/>
      </visual>
      <collision>
         <geometry>
            <box size="0.02 0.02 0.02" />
         </geometry>
         <origin xyz="0 0 0" rpy="0 0 0"/>
      </collision>
   </link>

   <!-- Lidar -->

   <link name="lidar">
      <inertial>
         <mass value="0.2"/>
         <origin xyz="0 0 0" rpy="0 0 0"/>
         <inertia ixx="0.01" ixy="0.0" ixz="0.0" iyy="0.01" iyz="0.0" izz="0.01"/>
      </inertial>
      <visual>
         <geometry>
            <cylinder radius="0.05" length="0.05" />
         </geometry>
         <origin xyz="0 0 0" rpy="0 0 0"/>
         <material name="white"/>
      </visual>
      <collision>
         <geometry>
            <box size="0.1 0.1 0.05"/>
         </geometry>
         <origin xyz="0 0 0" rpy="0 0 0"/>
      </collision>
   </link>
   
   <xacro:macro name="third_link" params="prefix">
      <link name="${prefix}_third_link">
         <inertial>
         <mass value="1.0"/>
         <origin xyz="0 0 0" rpy="0 0 0"/>
         <inertia ixx="0.01" ixy="0.0" ixz="0.0" iyy="0.01" iyz="0.0" izz="0.004"/>
      </inertial>
      <visual>
         <geometry>
            <box size="0.6 0.06 0.05"/>
         </geometry>
         <origin xyz="0 0 0" rpy="0 0 0"/>
         <material name="green"/>
      </visual>
      <collision>
         <geometry>
            <box size="0.6 0.06 0.05" />
         </geometry>
         <origin xyz="0 0 0" rpy="0 0 0"/>
      </collision>
      </link>
   </xacro:macro>
   
   <xacro:third_link prefix="right" />
   <xacro:third_link prefix="left" />
   
   <xacro:macro name="sec_link" params="prefix">
      <link name="${prefix}_sec_link">
         <inertial>
         <mass value="0.5"/>
         <origin xyz="0 0 0" rpy="0 0 0"/>
         <inertia ixx="0.005" ixy="0.0" ixz="0.0" iyy="0.005" iyz="0.0" izz="0.002"/>
      </inertial>
      <visual>
         <geometry>
            <box size="0.06 0.06 0.025" />
         </geometry>
         <origin xyz="0 0 0" rpy="0 0 0"/>
         <material name="green"/>
      </visual>
      <collision>
         <geometry>
            <box size="0.06 0.06 0.025" />
         </geometry>
         <origin xyz="0 0 0" rpy="0 0 0"/>
      </collision>
      </link>
   </xacro:macro>
   
   <xacro:sec_link prefix="left" />
   <xacro:sec_link prefix="right" />
   
   <!-- Wheels -->

   <xacro:macro name="wheel_link" params="prefix">
      <link name="${prefix}_wheel">
         <inertial>
            <mass value="0.5"/>
            <origin xyz="0 0 0" rpy="0 0 0"/>
            <inertia ixx="0.02" ixy="0.0" ixz="0.0" iyy="0.02" iyz="0.0" izz="0.02"/>
         </inertial>
         <visual>
            <geometry>
               <cylinder radius="0.1" length="0.1" />
            </geometry>
            <origin xyz="0 0 0" rpy="1.57 0 0"/>
            <material name="white"/>
         </visual>
         <collision>
           <geometry>
              <cylinder radius="0.1" length="0.1" />
           </geometry>
           <origin xyz="0 0 0" rpy="1.57 0 0"/>
         </collision>
      </link>
   </xacro:macro>
   
   <xacro:wheel_link prefix="left" />
   <xacro:wheel_link prefix="right" />
   <xacro:wheel_link prefix="left2" />
   <xacro:wheel_link prefix="right2" />

   <!-- Joints -->
 
   <joint name="base_left_sec_link_joint" type="fixed">
      <parent link="base_link"/>
      <child link="left_sec_link"/>
      <origin xyz=" 0 0.225 0" rpy="0 0 0"/>
      <axis xyz="0 0 0"/>
   </joint>
 
   <joint name="base_right_sec_link_joint" type="fixed">
      <parent link="base_link"/>
      <child link="right_sec_link"/>
      <origin xyz=" 0 -0.225 0" rpy="0 0 0"/>
      <axis xyz="0 0 0"/>
   </joint>
   
   <joint name="right_sec_third_link_joint" type="fixed">
      <parent link="right_sec_link"/>
      <child link="right_third_link"/>
      <origin xyz=" 0 -0.06 0" rpy="0 0 0"/>
      <axis xyz="0 0 0"/>
   </joint>
   
   <joint name="left_sec_third_link_joint" type="fixed">
      <parent link="left_sec_link"/>
      <child link="left_third_link"/>
      <origin xyz=" 0 0.06 0" rpy="0 0 0"/>
      <axis xyz="0 0 0"/>
   </joint>
   
   <joint name="base_left_wheel_joint" type="continuous">
      <parent link="left_third_link"/>
      <child link="left_wheel"/>
      <origin xyz="-0.2 0.08 -0.1" rpy="0 0 0"/>
      <axis xyz="0 1 0"/>
   </joint>

   <joint name="base_left_wheel2_joint" type="continuous">
      <parent link="left_third_link"/>
      <child link="left2_wheel"/>
      <origin xyz="0.2 0.08 -0.1" rpy="0 0 0"/>
      <axis xyz="0 1 0"/>
   </joint>

   <joint name="base_right_wheel_joint" type="continuous">
      <parent link="right_third_link"/>
      <child link="right_wheel"/>
      <origin xyz="-0.2 -0.08 -0.1" rpy="0 0 0"/>
      <axis xyz="0 1 0"/>
   </joint>

   <joint name="base_right_wheel2_joint" type="continuous">
      <parent link="right_third_link"/>
      <child link="right2_wheel"/>
      <origin xyz="0.2 -0.08 -0.1" rpy="0 0 0"/>
      <axis xyz="0 1 0"/>
   </joint>
   
   <joint name="base_lidar_joint" type="fixed">
      <parent link="base_link"/>
      <child link="lidar"/>
      <origin xyz="0.2 0 0.075" rpy="0 0 0"/>
   </joint>
   
   <joint name="base_camera_joint" type="fixed">
      <parent link="base_link"/>
      <child link="camera"/>
      <origin xyz="0.325 0 0.02" rpy="0 0 0"/>
   </joint>
   
   <joint name="base_ultrasonic_joint" type="fixed">
      <parent link="base_link"/>
      <child link="ultrasonic"/>
      <origin xyz="0.31 0 -0.03" rpy="0 0 0"/>
   </joint>
   
   <joint name="base_ultrasonic2_joint" type="fixed">
      <parent link="base_link"/>
      <child link="ultrasonic2"/>
      <origin xyz="-0.31 0 -0.03" rpy="0 0 0"/>
   </joint>
   
   <joint name="base_gps_joint" type="fixed">
      <parent link="base_link"/>
      <child link="gps"/>
      <origin xyz="0 0 -0.06" rpy="0 0 0"/>
   </joint>
   
   <joint name="base_joint" type="fixed">
      <parent link="base_footprint"/>
      <child link="base_link"/>
      <origin xyz="0 0 0.2" rpy="0 0 0"/>
   </joint>
   

</robot>
